<?xml version="1.0"?>
<mujoco xmlns:xacro="http://ros.org/wiki/xacro" model="Tiago Scene">
	<compiler angle="radian" autolimits="true" balanceinertia="true" />
	<option noslip_iterations="1" />
	<size njmax="500" nconmax="100" />

	<statistic center="0 0 0.3" extent="1.2" />

	<xacro:include filename="$(find mujoco_ycb)/assets/xacro/clf_pringles/assets.xml.xacro" />
    <xacro:include filename="$(find mujoco_ycb)/assets/xacro/clf_pringles/model.xml.xacro" />

    <xacro:include filename="$(find mujoco_ycb)/assets/xacro/ycb_orange/assets.xml.xacro" />
    <xacro:include filename="$(find mujoco_ycb)/assets/xacro/ycb_orange/model.xml.xacro" />

	<xacro:include filename="$(find tobi_sim)/assets/xacro/human_assets.xml.xacro" />
    <xacro:include filename="$(find tobi_sim)/assets/xacro/human_avatar.xml.xacro" />

	<xacro:clf_pringles_assets />
    <xacro:ycb_orange_assets />
	<xacro:human_assets />


	<visual>
		<headlight diffuse="0.6 0.6 0.6" ambient="0.3 0.3 0.3" specular="0 0 0" />
		<rgba haze="0.15 0.25 0.35 1" />
		<global azimuth="120" elevation="-20" />
	</visual>

	<asset>
		<texture type="skybox" builtin="gradient" rgb1="0.3 0.5 0.7" rgb2="0 0 0" width="512"
			height="3072" />
		<texture type="2d" name="groundplane" builtin="checker" mark="edge" rgb1="0.2 0.3 0.4"
			rgb2="0.1 0.2 0.3" markrgb="0.8 0.8 0.8" width="300" height="300" />
		<material name="groundplane" texture="groundplane" texuniform="true" texrepeat="5 5"
			reflectance="0.2" />

		<texture name="grid" type="2d" builtin="checker" width="512" height="512" rgb1=".1 .2 .3"
			rgb2=".2 .3 .4" />
		<material name="grid" texture="grid" texrepeat="1 1" texuniform="true" reflectance=".2" />
	</asset>

	<worldbody>
		<light pos="0 0 1.5" dir="0 0 -1" directional="true" />
		<geom name="floor" size="0 0 0.05" type="plane" material="groundplane" />
	</worldbody>

	<xacro:include filename="$(find tobi_sim)/scenes/makros/add_robot.xml.xacro" />
	<xacro:add_robot robot_name="tiago" robot_pos="0 0 0" robot_rot="0 0 0" />

	<worldbody>
		<geom name="wall1" pos="2.498 7.710 0.250" size="1.985 0.050 0.250" euler="0 0 0.071"
			type="box" rgba="0.5 0.5 0.5 1" />
		<geom name="wall2" pos="7.485 8.046 0.250" size="3.013 0.050 0.250" euler="0 0 0.065"
			type="box" rgba="0.5 0.5 0.5 1" />
		<geom name="wall3" pos="10.671 5.247 0.250" size="3.000 0.050 0.250" euler="0 0 -1.511"
			type="box" rgba="0.5 0.5 0.5 1" />
		<geom name="wall4" pos="9.873 2.201 0.250" size="0.978 0.050 0.250" euler="0 0 -3.089"
			type="box" rgba="0.5 0.5 0.5 1" />
		<geom name="wall5" pos="10.962 0.255 0.250" size="2.001 0.050 0.250" euler="0 0 -1.515"
			type="box" rgba="0.5 0.5 0.5 1" />
		<geom name="wall6" pos="8.593 -1.895 0.250" size="2.485 0.050 0.250" euler="0 0 -3.081"
			type="box" rgba="0.5 0.5 0.5 1" />
		<geom name="wall7" pos="6.049 -1.041 0.250" size="1.007 0.050 0.250" euler="0 0 1.634"
			type="box" rgba="0.5 0.5 0.5 1" />
		<geom name="wall8" pos="3.633 -2.222 0.250" size="2.486 0.050 0.250" euler="0 0 -3.071"
			type="box" rgba="0.5 0.5 0.5 1" />
		<geom name="wall9" pos="1.081 -1.396 0.250" size="1.003 0.050 0.250" euler="0 0 1.642"
			type="box" rgba="0.5 0.5 0.5 1" />
		<geom name="wall10" pos="0.941 1.072 0.250" size="0.599 0.050 0.250" euler="0 0 1.631"
			type="box" rgba="0.5 0.5 0.5 1" />
		<geom name="wall11" pos="2.409 1.746 0.250" size="1.505 0.050 0.250" euler="0 0 0.050"
			type="box" rgba="0.5 0.5 0.5 1" />
		<geom name="wall12" pos="0.865 2.193 0.250" size="0.524 0.050 0.250" euler="0 0 1.647"
			type="box" rgba="0.5 0.5 0.5 1" />
		<geom name="wall13" pos="1.759 3.676 0.250" size="0.975 0.050 0.250" euler="0 0 0.070"
			type="box" rgba="0.5 0.5 0.5 1" />
		<geom name="wall14" pos="0.652 5.588 0.250" size="1.984 0.050 0.250" euler="0 0 1.638"
			type="box" rgba="0.5 0.5 0.5 1" />
		<geom name="wall15" pos="4.251 3.832 0.250" size="0.524 0.050 0.250" euler="0 0 0.076"
			type="box" rgba="0.5 0.5 0.5 1" />
		<geom name="wall16" pos="4.626 5.861 0.250" size="1.995 0.050 0.250" euler="0 0 1.645"
			type="box" rgba="0.5 0.5 0.5 1" />
		<geom name="wall17" pos="5.319 1.894 0.250" size="0.499 0.050 0.250" euler="0 0 0.064"
			type="box" rgba="0.5 0.5 0.5 1" />
		<geom name="wall18" pos="5.866 1.427 0.250" size="0.501 0.050 0.250" euler="0 0 -1.475"
			type="box" rgba="0.5 0.5 0.5 1" />
		<geom name="wall19" pos="6.851 2.013 0.250" size="1.036 0.050 0.250" euler="0 0 0.085"
			type="box" rgba="0.5 0.5 0.5 1" />
	</worldbody>

	<asset>
		<material name="misc/seating" />
		<mesh name="misc/seating_COLLISION"
			file="$(find ecwm_data)/models/misc/seating/meshes/collision.stl" />
		<mesh name="misc/seating" file="$(find ecwm_data)/models/misc/seating/meshes/textured.stl" />
	</asset>
	<contact>
		<exclude body1="dishwasher" body2="dishwasher_door" />
		<exclude body1="dishwasher" body2="dishwasher_drawer_lower" />
		<exclude body1="dishwasher" body2="dishwasher_drawer_upper" />
	</contact>
	<asset />
	<worldbody>
		<body name="washingmaschine" pos="5.658462047576904 -0.971213698387146 0"
			quat="-0.02897400681516465 4.0457522220899846e-10 1.3402909679074348e-09 0.999580165333964">
			<geom type="box" size="0.3 0.3 0.425" pos="0 0 0.425" quat="1 0 0 0" />
		</body>
		<body name="wall_4" pos="6.104307651519775 -0.8419799208641052 3.3527612686157227e-07"
			quat="0.9995062151309462 -2.41655490780669e-08 -1.100961344497049e-08 0.03142174270485421">
			<geom type="box" size="0.05 0.4 1" pos="-0.05 0 1" quat="1 0 0 0" />
		</body>
		<body name="wall_3" pos="6.152462005615234 -1.6543262004852295 7.338821887969971e-07"
			quat="0.9997148048534122 -2.30484726816154e-08 -1.1270307933929542e-08 0.023881142286400186">
			<geom type="box" size="0.05 0.4 1" pos="-0.05 0 1" quat="1 0 0 0" />
		</body>
		<body name="wall_2" pos="8.53603458404541 -1.860910415649414 1.5869736671447754e-06"
			quat="0.6962954881211747 -5.1075384841798485e-08 -2.3256519875004202e-08 0.7177552460428918">
			<geom type="box" size="0.05 0.4 1" pos="-0.05 0 1" quat="1 0 0 0" />
		</body>
		<body name="wall_1" pos="6.535908222198486 -1.9599981307983398 1.257285475730896e-06"
			quat="0.6845936263344012 -5.1444005244362393e-08 -2.3416341154278974e-08 0.7289249390590988">
			<geom type="box" size="0.05 0.4 1" pos="-0.05 0 1" quat="1 0 0 0" />
		</body>
		<body name="tv_stand" pos="4.885616779327393 6.018153667449951 0"
			quat="-0.026212220312108236 -8.417049870878699e-13 1.5637258847026423e-09 0.9996564007229233">
			<geom type="box" size="0.03 0.37 0.2425" pos="0 0 0.6075" quat="1 0 0 0" />
			<geom type="box" size="0.1735 0.76 0.1825" pos="0 0 0.1825" quat="1 0 0 0" />
		</body>
		<body name="trash_bin" pos="6.596708297729492 -1.6754956245422363 1.8998980522155762e-07"
			quat="0.9998455855472655 -1.4333701708010158e-08 -3.448968328074148e-09 -0.01757285012869549">
			<geom type="box" size="0.025 0.025 0.025" pos="0 0 0.025" quat="1 0 0 0" />
		</body>
		<body name="sink" pos="7.65725564956665 -1.6599617004394531 0"
			quat="0.6868477137209862 0 0 0.7268013608657142">
			<geom type="box" size="0.215 0.6 0.1715" pos="-0.1275 0 1.7215" quat="1 0 0 0" />
			<geom type="box" size="0.14 0.6 0.25" pos="-0.2025 0 1.3" quat="1 0 0 0" />
			<geom type="box" size="0.3425 0.3 0.525" pos="0 -0.3 0.5025" quat="1 0 0 0" />
		</body>
		<body name="shelf" pos="5.284006118774414 2.102001667022705 9.872019290924072e-07"
			quat="0.9995322484121183 -6.764413950953164e-10 -6.135356181776e-08 0.030582419528409753">
			<geom type="box" size="0.38 0.1325 0.01" pos="0 0.007500000000000007 2.007"
				quat="1 0 0 0" />
			<geom type="box" size="0.38 0.1325 0.01" pos="0 0.007500000000000007 1.429"
				quat="1 0 0 0" />
			<geom type="box" size="0.38 0.1325 0.01" pos="0 0.007500000000000007 1.049"
				quat="1 0 0 0" />
			<geom type="box" size="0.38 0.1325 0.01" pos="0 0.007500000000000007 0.759"
				quat="1 0 0 0" />
			<geom type="box" size="0.38 0.1325 0.01"
				pos="0 0.007500000000000007 0.44000000000000006" quat="1 0 0 0" />
			<geom type="box" size="0.38 0.1325 0.01"
				pos="0 0.007500000000000007 0.09000000000000001" quat="1 0 0 0" />
			<geom type="box" size="0.38 0.007500000000000007 1.01" pos="0 -0.1325 1.01"
				quat="1 0 0 0" />
			<geom type="box" size="0.01 0.14 1.01" pos="0.39 0 1.01" quat="1 0 0 0" />
			<geom type="box" size="0.01 0.14 1.01" pos="-0.39 0 1.01" quat="1 0 0 0" />
		</body>
		<body name="night_stand" pos="4.260159492492676 4.56071662902832 0"
			quat="-0.015960043384359895 1.4529149665069498e-11 9.834614288407655e-10 0.9998726303960767">
			<geom type="box" size="0.25 0.25 0.25" pos="0 0 0.25" quat="1 0 0 0" />
		</body>
		<body name="kitchen_counter" pos="6.916921138763428 1.4336552619934082 0"
			quat="0.6906426435978936 -2.2696938401593248e-10 9.100149373957736e-10 0.7231961966466036">
			<geom type="box" size="0.5 0.5 0.5" pos="0 0 0.5" quat="1 0 0 0" />
		</body>
		<body name="garbage_bin" pos="4.960423469543457 4.344700336456299 0"
			quat="0.9998455855472655 -1.4333701708010158e-08 -3.448968328074148e-09 -0.01757285012869549">
			<geom type="box" size="0.025 0.025 0.025" pos="0 0 0.025" quat="1 0 0 0" />
		</body>
		<body name="fridge" pos="7.662601470947266 -1.6627413034439087 0"
			quat="0.6868477137209862 0 0 0.7268013608657142">
			<geom type="box" size="0.3425 0.3 0.525" pos="0 0.3 0.5025" quat="1 0 0 0" />
		</body>
		<body name="dresser" pos="0.9144766926765442 4.809781074523926 0"
			quat="-0.04235903833446693 -8.332604577297311e-11 2.5689072573684127e-09 0.9991024531405072">
			<geom type="box" size="0.1515 0.31 0.3475" pos="0 0 0.3475" quat="1 0 0 0" />
		</body>
		<body name="drawer" pos="6.053994178771973 7.8024821281433105 0"
			quat="-0.008640857237164429 -5.687957974622105e-11 2.9145998908278466e-10 0.9999626670962307">
			<geom type="box" size="0.17 0.15 0.28" pos="0 0 0.28" quat="1 0 0 0" />
		</body>
		<body name="dishwasher" pos="8.555129051208496 -1.562673807144165 0"
			quat="0.9996288385807544 -1.8498175152824488e-09 1.6130728644026446e-10 0.027243073939851304">
			<body name="dishwasher_door" pos="0 0.26 0.15" quat="0 0 0 1">
				<geom type="box" size="0.025 0.025 0.025" pos="0 0 0" quat="1 0 0 0" />
				<geom type="box" size="0.3 0.025 0.362" pos="0 0 0.2975" quat="1 0 0 0" />
				<joint type="hinge" axis="0 1 0" range="0 1.57" />
			</body>
			<body name="dishwasher_drawer_lower" pos="0 -0.05 0.24" quat="1 0 0 0">
				<geom type="box" size="0.01 0.125 0.1" pos="0 0.085 0.1" quat="1 0 0 0" />
				<geom type="box" size="0.005 0.26 0.05" pos="-0.2575 0 0.05" quat="1 0 0 0" />
				<geom type="box" size="0.005 0.26 0.05" pos="0.2575 0 0.05" quat="1 0 0 0" />
				<geom type="box" size="0.2625 0.005 0.05" pos="0 -0.255 0.05" quat="1 0 0 0" />
				<geom type="box" size="0.2625 0.005 0.05" pos="0 0.255 0.05" quat="1 0 0 0" />
				<geom type="box" size="0.2625 0.26 0.005" pos="0 0 0.005" quat="1 0 0 0" />
				<joint type="slide" axis="0 1 0" range="0 0.54" />
			</body>
			<body name="dishwasher_drawer_upper" pos="0 -0.05 0.57" quat="1 0 0 0">
				<geom type="box" size="0.005 0.2425 0.0675" pos="-0.2575 0 0.0675" quat="1 0 0 0" />
				<geom type="box" size="0.005 0.2425 0.0675" pos="0.2575 0 0.0675" quat="1 0 0 0" />
				<geom type="box" size="0.2575 0.005 0.0675" pos="0 -0.2375 0.0675" quat="1 0 0 0" />
				<geom type="box" size="0.2575 0.005 0.0675" pos="0 0.2375 0.0675" quat="1 0 0 0" />
				<geom type="box" size="0.2575 0.2425 0.005" pos="0 0 0.005" quat="1 0 0 0" />
				<joint type="slide" axis="0 1 0" range="0 0.52" />
			</body>
			<geom type="box" size="0.3 0.295 0.0425" pos="0 0 0.0425" quat="1 0 0 0" />
			<geom type="box" size="0.3 0.01 0.42" pos="0 -0.285 0.42" quat="1 0 0 0" />
			<geom type="box" size="0.01 0.27 0.42" pos="0.29 -0.025 0.42" quat="1 0 0 0" />
			<geom type="box" size="0.01 0.27 0.42" pos="-0.29 -0.025 0.42" quat="1 0 0 0" />
			<geom type="box" size="0.3 0.295 0.015" pos="0 0 0.825" quat="1 0 0 0" />
		</body>
		<body name="dining_table" pos="9.64711856842041 0.36319079995155334 0"
			quat="-0.2098684489713483 1.583989073518146e-10 1.2484903954687643e-08 0.977729632427268">
			<geom type="box" size="0.085 0.085 0.3575" pos="0 0 0.3575" quat="1 0 0 0" />
			<geom type="box" size="0.3425 0.3425 0.01" pos="0 0 0.715" quat="1 0 0 0" />
		</body>
		<body name="desk" pos="3.0995519161224365 -1.323012113571167 0"
			quat="-0.34838101187286763 -2.1272931977855596e-10 2.0546657661071087e-08 0.9373530127793032">
			<geom type="box" size="0.06 0.06 0.36" pos="-0.35 -0.7005 0.36" quat="1 0 0 0" />
			<geom type="box" size="0.06 0.06 0.36" pos="0.35 -0.7005 0.36" quat="1 0 0 0" />
			<geom type="box" size="0.06 0.06 0.36" pos="-0.35 0.7005 0.36" quat="1 0 0 0" />
			<geom type="box" size="0.06 0.06 0.36" pos="0.35 0.7005 0.36" quat="1 0 0 0" />
			<geom type="box" size="0.4 0.8 0.0125" pos="0 0 0.7175" quat="1 0 0 0" />
		</body>
		<body name="couch_table" pos="8.048605918884277 5.848633766174316 0"
			quat="1.9470718377062835e-07 0 0 0.9999999999999811">
			<geom type="cylinder" size="0.2 0.005" pos="0 0 0.005" quat="1 0 0 0" />
			<geom type="cylinder" size="0.1 0.26" pos="0 0 0.26" quat="1 0 0 0" />
			<geom type="cylinder" size="0.4 0.01" pos="0 0 0.53" quat="1 0 0 0" />
		</body>
		<body name="coat_hanger" pos="10.061262130737305 7.823883533477783 0"
			quat="1.9470718377062835e-07 0 0 0.9999999999999811">
			<geom type="cylinder" size="0.225 0.85" pos="0 0 0.85" quat="1 0 0 0" />
		</body>
		<body name="cabinet" pos="3.3436827659606934 1.5821243524551392 0"
			quat="-0.023799261048375854 -3.435410285265514e-11 1.4772006932456075e-09 0.9997167574736113">
			<geom type="box" size="0.38 0.1325 0.01" pos="0 0.007500000000000007 2.007"
				quat="1 0 0 0" />
			<geom type="box" size="0.38 0.1325 0.01" pos="0 0.007500000000000007 1.429"
				quat="1 0 0 0" />
			<geom type="box" size="0.38 0.1325 0.01" pos="0 0.007500000000000007 1.049"
				quat="1 0 0 0" />
			<geom type="box" size="0.38 0.1325 0.01" pos="0 0.007500000000000007 0.759"
				quat="1 0 0 0" />
			<geom type="box" size="0.38 0.1325 0.01"
				pos="0 0.007500000000000007 0.44000000000000006" quat="1 0 0 0" />
			<geom type="box" size="0.38 0.1325 0.01"
				pos="0 0.007500000000000007 0.09000000000000001" quat="1 0 0 0" />
			<geom type="box" size="0.38 0.007500000000000007 1.01" pos="0 -0.1325 1.01"
				quat="1 0 0 0" />
			<geom type="box" size="0.01 0.14 1.01" pos="0.39 0 1.01" quat="1 0 0 0" />
			<geom type="box" size="0.01 0.14 1.01" pos="-0.39 0 1.01" quat="1 0 0 0" />
		</body>
		<body name="bed" pos="1.7459826469421387 5.820728778839111 4.76837158203125e-07"
			quat="-0.025032011954692995 2.680273598670238e-10 1.7658886486176809e-09 0.9996866500946685">
			<geom type="box" size="0.035 0.51 0.325" pos="1.035 0 0.325" quat="1 0 0 0" />
			<geom type="box" size="0.035 0.51 0.325" pos="-1.035 0 0.325" quat="1 0 0 0" />
			<geom type="box" size="1 0.51 0.24" pos="0 0 0.24" quat="1 0 0 0" />
		</body>
		<body name="bar" pos="9.598333358764648 2.5869030952453613 3.725290298461914e-09"
			quat="-0.022114964028054965 -2.206501491923298e-10 1.4841266987394807e-09 0.9997554342768225">
			<geom type="box" size="0.25 0.25 0.25" pos="0 0 0.25" quat="1 0 0 0" />
		</body>
		<body name="arm_chair" pos="10.000221252441406 3.2475147247314453 3.725290298461914e-09"
			quat="-0.33732443731400064 5.511213515940126e-11 2.0109668407987775e-08 0.9413884554161436">
			<geom type="box" size="0.24 0.025 0.25" pos="0 0.275 0.62" quat="1 0 0 0" />
			<geom type="box" size="0.025 0.275 0.1" pos="0.25 0 0.47" quat="1 0 0 0" />
			<geom type="box" size="0.025 0.275 0.1" pos="-0.25 0 0.47" quat="1 0 0 0" />
			<geom type="box" size="0.24 0.275 0.185" pos="0 0 0.175" quat="1 0 0 0" />
		</body>
	</worldbody>

	<worldbody>
        <xacro:human_avatar name="human1" pos="8.5 6.8 0.95" rot="0 0 -1.56" gesture="waving_left" posture="standing" />
        <xacro:human_avatar name="human2" pos="10.5 0.5 0.95" rot="0 0 3.14" gesture="neutral" posture="sitting" />
    </worldbody>

	<worldbody>
        <xacro:clf_pringles_model name="pringles1" pos="8.8 -1.5 1.2" rot="0 0 0"/>
        <xacro:ycb_orange_model name="orange1" pos="6.85 1.5 1.2" rot="0 0 0"/>
    </worldbody>


</mujoco>